<?xml version="1.0" ?>
<sdf version="1.8">
  <model name="autocar">
    <pose>0 0 0.0 0 0 0</pose>

    <link name='base_link' />

    <joint name='chassis_link_joint' type='fixed'>
      <parent>base_link</parent>
      <child>chassis_link</child>
    </joint>

    <link name='chassis_link'>
      <inertial>
        <pose>1e-06 0.07307 0.65096 0 -0 0</pose>
        <mass>1580</mass>
        <inertia>
          <ixx>1997.86</ixx><ixy>-3e-05</ixy><ixz>-1e-06</ixz>
          <iyy>442.769</iyy><iyz>62.5206</iyz><izz>2238.05</izz>
        </inertia>
      </inertial>
      <collision name='chassis_link_collision'>
        <pose>0 0 0.46936 0 -0 0</pose>
        <geometry>
          <mesh>
            <scale>0.001 0.001 0.001</scale>
            <uri>model://autocar/meshes/chassis_link.stl</uri>
          </mesh>
        </geometry>
        <surface>
          <friction>
            <ode><mu>0.2</mu><mu2>0.2</mu2></ode>
          </friction>
        </surface>
      </collision>
      <collision name='spoiler_link_collision'>
        <pose>0 0.05 0.41936 1.5708 -0 3.14159</pose>
        <geometry>
          <mesh>
            <scale>0.001 0.001 0.001</scale>
            <uri>model://autocar/meshes/spoiler.stl</uri>
          </mesh>
        </geometry>
        <surface>
          <friction>
            <ode><mu>0.2</mu><mu2>0.2</mu2></ode>
          </friction>
        </surface>
      </collision>
      <visual name='chassis_link_visual'>
        <pose>0 0 0.46936 0 -0 0</pose>
        <geometry>
          <mesh>
            <scale>0.001 0.001 0.001</scale>
            <uri>model://autocar/meshes/chassis_link.stl</uri>
          </mesh>
        </geometry>
      </visual>
      <visual name='spoiler_link_visual'>
        <pose>0 0.05 0.41936 1.5708 -0 3.14159</pose>
        <geometry>
          <mesh>
            <scale>0.001 0.001 0.001</scale>
            <uri>model://autocar/meshes/spoiler.stl</uri>
          </mesh>
        </geometry>
      </visual>
    </link>

    <link name="hokuyo_link">
      <pose relative_to='base_link'>0 2.34 0.72 0 0 1.5708</pose>
      <sensor name="head_hokuyo_sensor" type="gpu_lidar">
        <always_on>true</always_on>
        <visualize>true</visualize>
        <update_rate>40</update_rate>
        <lidar>
          <scan>
            <horizontal>
              <samples>720</samples>
              <resolution>1</resolution>
              <min_angle>-1.570796</min_angle>
              <max_angle>1.570796</max_angle>
            </horizontal>
          </scan>
          <range>
            <min>0.12</min>
            <max>30.0</max>
            <resolution>0.01</resolution>
          </range>
        </lidar>
      </sensor>
    </link>
    <joint name="hokuyo_joint" type="fixed">
      <parent>base_link</parent>
      <child>hokuyo_link</child>
    </joint>

    <link name='bl_1'>
      <pose relative_to='bl_axle'>0 0 0 0 -0 0</pose>
      <inertial>
        <mass>24.5</mass>
        <inertia>
          <ixx>1.84514</ixx><ixy>0</ixy><ixz>0</ixz>
          <iyy>1.04961</iyy><iyz>0</iyz><izz>1.04961</izz>
        </inertia>
      </inertial>
      <collision name='bl_1_collision'>
        <pose>0 0 0 0 1.5708 0</pose>
        <geometry>
          <cylinder><radius>.3425</radius><length>.22</length></cylinder>
        </geometry>
        <surface>
          <friction>
            <ode><mu>1.7</mu><mu2>1.7</mu2></ode>
          </friction>
        </surface>
      </collision>
      <visual name='bl_1_visual'>
        <pose>0.875 1.0136 0.1444 0 -0 0</pose>
        <geometry>
          <mesh><scale>0.001 0.001 0.001</scale><uri>model://autocar/meshes/bl_1.stl</uri></mesh>
        </geometry>
      </visual>
    </link>
    <joint name='bl_axle' type='revolute'>
      <pose relative_to='chassis_link'>-0.875 -1.01364 0.324997 0 -0 0</pose>
      <parent>chassis_link</parent>
      <child>bl_1</child>
      <axis><xyz>-1 0 0</xyz></axis>
    </joint>

    <link name='br_1'>
      <pose relative_to='br_axle'>0 0 0 0 -0 0</pose>
      <inertial>
        <mass>24.5</mass>
        <inertia>
          <ixx>1.84514</ixx><ixy>0</ixy><ixz>0</ixz>
          <iyy>1.04961</iyy><iyz>0</iyz><izz>1.04961</izz>
        </inertia>
      </inertial>
      <collision name='br_1_collision'>
        <pose>0 0 0 0 1.5708 0</pose>
        <geometry>
          <cylinder><radius>.3425</radius><length>.22</length></cylinder>
        </geometry>
        <surface>
          <friction>
            <ode><mu>1.7</mu><mu2>1.7</mu2></ode>
          </friction>
        </surface>
      </collision>
      <visual name='br_1_visual'>
        <pose>-0.875 1.0136 0.1444 0 -0 0</pose>
        <geometry>
          <mesh><scale>0.001 0.001 0.001</scale><uri>model://autocar/meshes/br_1.stl</uri></mesh>
        </geometry>
      </visual>
    </link>
    <joint name='br_axle' type='revolute'>
      <pose relative_to='chassis_link'>0.875 -1.01364 0.324997 0 -0 0</pose>
      <parent>chassis_link</parent>
      <child>br_1</child>
      <axis><xyz>-1 0 0</xyz></axis>
    </joint>

    <link name='l_steer_1'>
      <pose relative_to='l_steer'>0 0 0 0 -0 0</pose>
      <inertial>
        <mass>1</mass>
        <inertia><ixx>1</ixx><ixy>0</ixy><ixz>0</ixz><iyy>1</iyy><iyz>0</iyz><izz>1</izz></inertia>
      </inertial>
    </link>
    <joint name='l_steer' type='revolute'>
      <pose relative_to='chassis_link'>-0.825 1.51736 0.324997 0 -0 0</pose>
      <parent>chassis_link</parent>
      <child>l_steer_1</child>
      <axis>
        <xyz>0 0 1</xyz>
        <limit><lower>-0.95</lower><upper>0.95</upper></limit>
      </axis>
    </joint>

    <link name='fl_1'>
      <pose relative_to='fl_axle'>0 0 0 0 -0 0</pose>
      <inertial>
        <mass>24.5</mass>
        <inertia>
          <ixx>1.84514</ixx><ixy>0</ixy><ixz>0</ixz>
          <iyy>1.04961</iyy><iyz>0</iyz><izz>1.04961</izz>
        </inertia>
      </inertial>
      <collision name='fl_1_collision'>
        <pose>0 0 0 0 1.5708 0</pose>
        <geometry>
           <cylinder><radius>.3425</radius><length>.22</length></cylinder>
        </geometry>
        <surface>
          <friction>
            <ode><mu>1.1</mu><mu2>1.1</mu2></ode>
          </friction>
        </surface>
      </collision>
      <visual name='fl_1_visual'>
        <pose>0.875 -1.5174 0.1444 0 -0 0</pose>
        <geometry>
          <mesh><scale>0.001 0.001 0.001</scale><uri>model://autocar/meshes/fl_1.stl</uri></mesh>
        </geometry>
      </visual>
    </link>
    <joint name='fl_axle' type='revolute'>
      <pose relative_to='l_steer_1'>-0.05 0 0 0 -0 0</pose>
      <parent>l_steer_1</parent>
      <child>fl_1</child>
      <axis><xyz>-1 0 0</xyz></axis>
    </joint>

    <link name='r_steer_1'>
      <pose relative_to='r_steer'>0 0 0 0 -0 0</pose>
      <inertial>
        <mass>1</mass>
        <inertia><ixx>1</ixx><ixy>0</ixy><ixz>0</ixz><iyy>1</iyy><iyz>0</iyz><izz>1</izz></inertia>
      </inertial>
    </link>
    <joint name='r_steer' type='revolute'>
      <pose relative_to='chassis_link'>0.825 1.51736 0.324997 0 -0 0</pose>
      <parent>chassis_link</parent>
      <child>r_steer_1</child>
      <axis>
        <xyz>0 0 1</xyz>
        <limit><lower>-0.95</lower><upper>0.95</upper></limit>
      </axis>
    </joint>

    <link name='fr_1'>
      <pose relative_to='fr_axle'>0 0 0 0 -0 0</pose>
      <inertial>
        <mass>24.5</mass>
        <inertia>
          <ixx>1.84514</ixx><ixy>0</ixy><ixz>0</ixz>
          <iyy>1.04961</iyy><iyz>0</iyz><izz>1.04961</izz>
        </inertia>
      </inertial>
      <collision name='fr_1_collision'>
        <pose>0 0 0 0 1.5708 0</pose>
        <geometry>
           <cylinder><radius>.3425</radius><length>.22</length></cylinder>
        </geometry>
        <surface>
          <friction>
            <ode><mu>1.7</mu><mu2>1.7</mu2></ode>
          </friction>
        </surface>
      </collision>
      <visual name='fr_1_visual'>
        <pose>-0.875 -1.5174 0.1444 0 -0 0</pose>
        <geometry>
          <mesh><scale>0.001 0.001 0.001</scale><uri>model://autocar/meshes/fr_1.stl</uri></mesh>
        </geometry>
      </visual>
    </link>
    <joint name='fr_axle' type='revolute'>
      <pose relative_to='r_steer_1'>0.05 0 0 0 -0 0</pose>
      <parent>r_steer_1</parent>
      <child>fr_1</child>
      <axis><xyz>-1 0 0</xyz></axis>
    </joint>

    <link name="steering_wheel" />
    <joint name="steering_joint" type="revolute">
      <pose>-0.002 0 0 0 0 0</pose>
      <parent>chassis_link</parent>
      <child>steering_wheel</child>
      <axis>
        <xyz>-0.964118 0.000768 0.265556</xyz>
        <limit><lower>-7.85</lower><upper>7.85</upper></limit>
        <dynamics><damping>1.0</damping></dynamics>
      </axis>
    </joint>

    <plugin
      filename="gz-sim-ackermann-steering-system"
      name="gz::sim::systems::AckermannSteering">
      <left_steering_joint>l_steer</left_steering_joint>
      <right_steering_joint>r_steer</right_steering_joint>
      <left_rear_wheel_joint>bl_axle</left_rear_wheel_joint>
      <right_rear_wheel_joint>br_axle</right_rear_wheel_joint>
      <left_front_wheel_joint>fl_axle</left_front_wheel_joint>
      <right_front_wheel_joint>fr_axle</right_front_wheel_joint>
      <wheel_base>2.534</wheel_base>
      <wheel_separation>1.75</wheel_separation>
      <kingpin_width>1.65</kingpin_width>
      <steering_limit>0.95</steering_limit>
      <topic>/model/autocar/cmd_vel</topic>
      <odom_topic>/model/autocar/odometry</odom_topic>
      <tf_topic>/model/autocar/tf</tf_topic>
      <frame_id>odom</frame_id>
      <child_frame_id>base_link</child_frame_id>
    </plugin>

    <plugin
      filename="gz-sim-joint-state-publisher-system"
      name="gz::sim::systems::JointStatePublisher">
    </plugin>
  </model>
</sdf>